05-05 13:48:12 - ERROR - [recognize.py:14 - <module>] - RapidOCR 导入失败:Traceback (most recent call last):
  File "c:\Users\mark_hoshipu\Desktop\CannotMax-QT\src\recogize\recognize.py", line 10, in <module>
    from rapidocr_onnxruntime import RapidOCR
ModuleNotFoundError: No module named 'rapidocr_onnxruntime'

05-05 13:48:23 - ERROR - [recognize.py:14 - <module>] - RapidOCR 导入失败:Traceback (most recent call last):
  File "c:\Users\mark_hoshipu\Desktop\CannotMax-QT\src\recogize\recognize.py", line 10, in <module>
    from rapidocr_onnxruntime import RapidOCR
ModuleNotFoundError: No module named 'rapidocr_onnxruntime'

05-05 13:50:52 - ERROR - [recognize.py:15 - <module>] - RapidOCR 导入失败:Traceback (most recent call last):
  File "c:\Users\mark_hoshipu\Desktop\CannotMax-QT\src\recogize\recognize.py", line 11, in <module>
    from rapidocr_onnxruntime import RapidOCR
  File "C:\Users\mark_hoshipu\AppData\Local\Programs\Python\Python312\Lib\site-packages\rapidocr_onnxruntime\__init__.py", line 4, in <module>
    from .main import RapidOCR
  File "C:\Users\mark_hoshipu\AppData\Local\Programs\Python\Python312\Lib\site-packages\rapidocr_onnxruntime\main.py", line 12, in <module>
    from .ch_ppocr_cls import TextClassifier
  File "C:\Users\mark_hoshipu\AppData\Local\Programs\Python\Python312\Lib\site-packages\rapidocr_onnxruntime\ch_ppocr_cls\__init__.py", line 4, in <module>
    from .text_cls import TextClassifier
  File "C:\Users\mark_hoshipu\AppData\Local\Programs\Python\Python312\Lib\site-packages\rapidocr_onnxruntime\ch_ppocr_cls\text_cls.py", line 22, in <module>
    from rapidocr_onnxruntime.utils import OrtInferSession, read_yaml
  File "C:\Users\mark_hoshipu\AppData\Local\Programs\Python\Python312\Lib\site-packages\rapidocr_onnxruntime\utils\__init__.py", line 9, in <module>
    from .infer_engine import OrtInferSession
  File "C:\Users\mark_hoshipu\AppData\Local\Programs\Python\Python312\Lib\site-packages\rapidocr_onnxruntime\utils\infer_engine.py", line 12, in <module>
    from onnxruntime import (
  File "C:\Users\mark_hoshipu\AppData\Local\Programs\Python\Python312\Lib\site-packages\onnxruntime\__init__.py", line 61, in <module>
    raise import_capi_exception
  File "C:\Users\mark_hoshipu\AppData\Local\Programs\Python\Python312\Lib\site-packages\onnxruntime\__init__.py", line 24, in <module>
    from onnxruntime.capi._pybind_state import (
  File "C:\Users\mark_hoshipu\AppData\Local\Programs\Python\Python312\Lib\site-packages\onnxruntime\capi\_pybind_state.py", line 32, in <module>
    from .onnxruntime_pybind11_state import *  # noqa
    ^^^^^^^^^^^^^^^^^^^^^^^^^^^^^^^^^^^^^^^^^
ImportError: DLL load failed while importing onnxruntime_pybind11_state: 动态链接库(DLL)初始化例程失败。

05-05 13:52:58 - ERROR - [recognize.py:15 - <module>] - RapidOCR 导入失败:Traceback (most recent call last):
  File "c:\Users\mark_hoshipu\Desktop\CannotMax-QT\src\recogize\recognize.py", line 11, in <module>
    from rapidocr_onnxruntime import RapidOCR
  File "C:\Users\mark_hoshipu\AppData\Local\Programs\Python\Python312\Lib\site-packages\rapidocr_onnxruntime\__init__.py", line 4, in <module>
    from .main import RapidOCR
  File "C:\Users\mark_hoshipu\AppData\Local\Programs\Python\Python312\Lib\site-packages\rapidocr_onnxruntime\main.py", line 12, in <module>
    from .ch_ppocr_cls import TextClassifier
  File "C:\Users\mark_hoshipu\AppData\Local\Programs\Python\Python312\Lib\site-packages\rapidocr_onnxruntime\ch_ppocr_cls\__init__.py", line 4, in <module>
    from .text_cls import TextClassifier
  File "C:\Users\mark_hoshipu\AppData\Local\Programs\Python\Python312\Lib\site-packages\rapidocr_onnxruntime\ch_ppocr_cls\text_cls.py", line 22, in <module>
    from rapidocr_onnxruntime.utils import OrtInferSession, read_yaml
  File "C:\Users\mark_hoshipu\AppData\Local\Programs\Python\Python312\Lib\site-packages\rapidocr_onnxruntime\utils\__init__.py", line 9, in <module>
    from .infer_engine import OrtInferSession
  File "C:\Users\mark_hoshipu\AppData\Local\Programs\Python\Python312\Lib\site-packages\rapidocr_onnxruntime\utils\infer_engine.py", line 12, in <module>
    from onnxruntime import (
  File "C:\Users\mark_hoshipu\AppData\Local\Programs\Python\Python312\Lib\site-packages\onnxruntime\__init__.py", line 61, in <module>
    raise import_capi_exception
  File "C:\Users\mark_hoshipu\AppData\Local\Programs\Python\Python312\Lib\site-packages\onnxruntime\__init__.py", line 24, in <module>
    from onnxruntime.capi._pybind_state import (
  File "C:\Users\mark_hoshipu\AppData\Local\Programs\Python\Python312\Lib\site-packages\onnxruntime\capi\_pybind_state.py", line 32, in <module>
    from .onnxruntime_pybind11_state import *  # noqa
    ^^^^^^^^^^^^^^^^^^^^^^^^^^^^^^^^^^^^^^^^^
ImportError: DLL load failed while importing onnxruntime_pybind11_state: 动态链接库(DLL)初始化例程失败。

05-05 13:54:22 - ERROR - [recognize.py:15 - <module>] - RapidOCR 导入失败:Traceback (most recent call last):
  File "c:\Users\mark_hoshipu\Desktop\CannotMax-QT\src\recogize\recognize.py", line 11, in <module>
    from rapidocr_onnxruntime import RapidOCR
  File "C:\Users\mark_hoshipu\AppData\Local\Programs\Python\Python312\Lib\site-packages\rapidocr_onnxruntime\__init__.py", line 4, in <module>
    from .main import RapidOCR
  File "C:\Users\mark_hoshipu\AppData\Local\Programs\Python\Python312\Lib\site-packages\rapidocr_onnxruntime\main.py", line 12, in <module>
    from .ch_ppocr_cls import TextClassifier
  File "C:\Users\mark_hoshipu\AppData\Local\Programs\Python\Python312\Lib\site-packages\rapidocr_onnxruntime\ch_ppocr_cls\__init__.py", line 4, in <module>
    from .text_cls import TextClassifier
  File "C:\Users\mark_hoshipu\AppData\Local\Programs\Python\Python312\Lib\site-packages\rapidocr_onnxruntime\ch_ppocr_cls\text_cls.py", line 22, in <module>
    from rapidocr_onnxruntime.utils import OrtInferSession, read_yaml
  File "C:\Users\mark_hoshipu\AppData\Local\Programs\Python\Python312\Lib\site-packages\rapidocr_onnxruntime\utils\__init__.py", line 9, in <module>
    from .infer_engine import OrtInferSession
  File "C:\Users\mark_hoshipu\AppData\Local\Programs\Python\Python312\Lib\site-packages\rapidocr_onnxruntime\utils\infer_engine.py", line 12, in <module>
    from onnxruntime import (
  File "C:\Users\mark_hoshipu\AppData\Local\Programs\Python\Python312\Lib\site-packages\onnxruntime\__init__.py", line 61, in <module>
    raise import_capi_exception
  File "C:\Users\mark_hoshipu\AppData\Local\Programs\Python\Python312\Lib\site-packages\onnxruntime\__init__.py", line 24, in <module>
    from onnxruntime.capi._pybind_state import (
  File "C:\Users\mark_hoshipu\AppData\Local\Programs\Python\Python312\Lib\site-packages\onnxruntime\capi\_pybind_state.py", line 32, in <module>
    from .onnxruntime_pybind11_state import *  # noqa
    ^^^^^^^^^^^^^^^^^^^^^^^^^^^^^^^^^^^^^^^^^
ImportError: DLL load failed while importing onnxruntime_pybind11_state: 动态链接库(DLL)初始化例程失败。

05-05 13:59:19 - ERROR - [recognize.py:15 - <module>] - RapidOCR 导入失败:Traceback (most recent call last):
  File "c:\Users\mark_hoshipu\Desktop\CannotMax-QT\src\recogize\recognize.py", line 11, in <module>
    from rapidocr_onnxruntime import RapidOCR
  File "C:\Users\mark_hoshipu\AppData\Local\Programs\Python\Python312\Lib\site-packages\rapidocr_onnxruntime\__init__.py", line 4, in <module>
    from .main import RapidOCR
  File "C:\Users\mark_hoshipu\AppData\Local\Programs\Python\Python312\Lib\site-packages\rapidocr_onnxruntime\main.py", line 12, in <module>
    from .ch_ppocr_cls import TextClassifier
  File "C:\Users\mark_hoshipu\AppData\Local\Programs\Python\Python312\Lib\site-packages\rapidocr_onnxruntime\ch_ppocr_cls\__init__.py", line 4, in <module>
    from .text_cls import TextClassifier
  File "C:\Users\mark_hoshipu\AppData\Local\Programs\Python\Python312\Lib\site-packages\rapidocr_onnxruntime\ch_ppocr_cls\text_cls.py", line 22, in <module>
    from rapidocr_onnxruntime.utils import OrtInferSession, read_yaml
  File "C:\Users\mark_hoshipu\AppData\Local\Programs\Python\Python312\Lib\site-packages\rapidocr_onnxruntime\utils\__init__.py", line 9, in <module>
    from .infer_engine import OrtInferSession
  File "C:\Users\mark_hoshipu\AppData\Local\Programs\Python\Python312\Lib\site-packages\rapidocr_onnxruntime\utils\infer_engine.py", line 12, in <module>
    from onnxruntime import (
  File "C:\Users\mark_hoshipu\AppData\Local\Programs\Python\Python312\Lib\site-packages\onnxruntime\__init__.py", line 61, in <module>
    raise import_capi_exception
  File "C:\Users\mark_hoshipu\AppData\Local\Programs\Python\Python312\Lib\site-packages\onnxruntime\__init__.py", line 24, in <module>
    from onnxruntime.capi._pybind_state import (
  File "C:\Users\mark_hoshipu\AppData\Local\Programs\Python\Python312\Lib\site-packages\onnxruntime\capi\_pybind_state.py", line 32, in <module>
    from .onnxruntime_pybind11_state import *  # noqa
    ^^^^^^^^^^^^^^^^^^^^^^^^^^^^^^^^^^^^^^^^^
ImportError: DLL load failed while importing onnxruntime_pybind11_state: 动态链接库(DLL)初始化例程失败。

05-05 14:00:35 - ERROR - [recognize.py:15 - <module>] - RapidOCR 导入失败:Traceback (most recent call last):
  File "c:\Users\mark_hoshipu\Desktop\CannotMax-QT\src\recogize\recognize.py", line 12, in <module>
    rapid_ocr_instance = RapidOCR()
                         ^^^^^^^^^^
  File "C:\Users\mark_hoshipu\AppData\Local\Programs\Python\Python312\Lib\site-packages\rapidocr\main.py", line 60, in __init__
    self.text_det = TextDetector(config.Det)
                    ^^^^^^^^^^^^^^^^^^^^^^^^
  File "C:\Users\mark_hoshipu\AppData\Local\Programs\Python\Python312\Lib\site-packages\rapidocr\ch_ppocr_det\main.py", line 45, in __init__
    self.session = get_engine(config.engine_name)(config)
                   ^^^^^^^^^^^^^^^^^^^^^^^^^^^^^^
  File "C:\Users\mark_hoshipu\AppData\Local\Programs\Python\Python312\Lib\site-packages\rapidocr\inference_engine\base.py", line 44, in get_engine
    if not import_package("onnxruntime"):
           ^^^^^^^^^^^^^^^^^^^^^^^^^^^^^
  File "C:\Users\mark_hoshipu\AppData\Local\Programs\Python\Python312\Lib\site-packages\rapidocr\utils\utils.py", line 44, in import_package
    module = importlib.import_module(name, package=package)
             ^^^^^^^^^^^^^^^^^^^^^^^^^^^^^^^^^^^^^^^^^^^^^^
  File "C:\Users\mark_hoshipu\AppData\Local\Programs\Python\Python312\Lib\importlib\__init__.py", line 90, in import_module
    return _bootstrap._gcd_import(name[level:], package, level)
           ^^^^^^^^^^^^^^^^^^^^^^^^^^^^^^^^^^^^^^^^^^^^^^^^^^^^
  File "<frozen importlib._bootstrap>", line 1387, in _gcd_import
  File "<frozen importlib._bootstrap>", line 1360, in _find_and_load
  File "<frozen importlib._bootstrap>", line 1331, in _find_and_load_unlocked
  File "<frozen importlib._bootstrap>", line 935, in _load_unlocked
  File "<frozen importlib._bootstrap_external>", line 995, in exec_module
  File "<frozen importlib._bootstrap>", line 488, in _call_with_frames_removed
  File "C:\Users\mark_hoshipu\AppData\Local\Programs\Python\Python312\Lib\site-packages\onnxruntime\__init__.py", line 61, in <module>
    raise import_capi_exception
  File "C:\Users\mark_hoshipu\AppData\Local\Programs\Python\Python312\Lib\site-packages\onnxruntime\__init__.py", line 24, in <module>
    from onnxruntime.capi._pybind_state import (
  File "C:\Users\mark_hoshipu\AppData\Local\Programs\Python\Python312\Lib\site-packages\onnxruntime\capi\_pybind_state.py", line 32, in <module>
    from .onnxruntime_pybind11_state import *  # noqa
    ^^^^^^^^^^^^^^^^^^^^^^^^^^^^^^^^^^^^^^^^^
ImportError: DLL load failed while importing onnxruntime_pybind11_state: 动态链接库(DLL)初始化例程失败。

05-05 17:51:05 - ERROR - [recognize.py:15 - <module>] - RapidOCR 导入失败:Traceback (most recent call last):
  File "c:\Users\mark_hoshipu\Desktop\CannotMax-QT\src\recogize\recognize.py", line 12, in <module>
    rapid_ocr_instance = RapidOCR()
                         ^^^^^^^^^^
  File "C:\Users\mark_hoshipu\AppData\Local\Programs\Python\Python312\Lib\site-packages\rapidocr\main.py", line 60, in __init__
    self.text_det = TextDetector(config.Det)
                    ^^^^^^^^^^^^^^^^^^^^^^^^
  File "C:\Users\mark_hoshipu\AppData\Local\Programs\Python\Python312\Lib\site-packages\rapidocr\ch_ppocr_det\main.py", line 45, in __init__
    self.session = get_engine(config.engine_name)(config)
                   ^^^^^^^^^^^^^^^^^^^^^^^^^^^^^^
  File "C:\Users\mark_hoshipu\AppData\Local\Programs\Python\Python312\Lib\site-packages\rapidocr\inference_engine\base.py", line 44, in get_engine
    if not import_package("onnxruntime"):
           ^^^^^^^^^^^^^^^^^^^^^^^^^^^^^
  File "C:\Users\mark_hoshipu\AppData\Local\Programs\Python\Python312\Lib\site-packages\rapidocr\utils\utils.py", line 44, in import_package
    module = importlib.import_module(name, package=package)
             ^^^^^^^^^^^^^^^^^^^^^^^^^^^^^^^^^^^^^^^^^^^^^^
  File "C:\Users\mark_hoshipu\AppData\Local\Programs\Python\Python312\Lib\importlib\__init__.py", line 90, in import_module
    return _bootstrap._gcd_import(name[level:], package, level)
           ^^^^^^^^^^^^^^^^^^^^^^^^^^^^^^^^^^^^^^^^^^^^^^^^^^^^
  File "<frozen importlib._bootstrap>", line 1387, in _gcd_import
  File "<frozen importlib._bootstrap>", line 1360, in _find_and_load
  File "<frozen importlib._bootstrap>", line 1331, in _find_and_load_unlocked
  File "<frozen importlib._bootstrap>", line 935, in _load_unlocked
  File "<frozen importlib._bootstrap_external>", line 995, in exec_module
  File "<frozen importlib._bootstrap>", line 488, in _call_with_frames_removed
  File "C:\Users\mark_hoshipu\AppData\Local\Programs\Python\Python312\Lib\site-packages\onnxruntime\__init__.py", line 61, in <module>
    raise import_capi_exception
  File "C:\Users\mark_hoshipu\AppData\Local\Programs\Python\Python312\Lib\site-packages\onnxruntime\__init__.py", line 24, in <module>
    from onnxruntime.capi._pybind_state import (
  File "C:\Users\mark_hoshipu\AppData\Local\Programs\Python\Python312\Lib\site-packages\onnxruntime\capi\_pybind_state.py", line 32, in <module>
    from .onnxruntime_pybind11_state import *  # noqa
    ^^^^^^^^^^^^^^^^^^^^^^^^^^^^^^^^^^^^^^^^^
ImportError: DLL load failed while importing onnxruntime_pybind11_state: 动态链接库(DLL)初始化例程失败。

